Files already downloaded and verified
Files already downloaded and verified
Running Evolution for fitness
Initializing
Validation DataLoader 0:   0%|                                                                 | 0/157 [01:57<?, ?it/s]
  0%|                                                                                           | 0/20 [02:03<?, ?it/s]
  0%|                                                                                            | 0/1 [02:03<?, ?it/s]
Traceback (most recent call last):
  File "C:\Users\Jordan\anaconda3\envs\EC2\lib\site-packages\pytorch_lightning\trainer\trainer.py", line 724, in _call_and_handle_interrupt
    return trainer_fn(*args, **kwargs)
  File "C:\Users\Jordan\anaconda3\envs\EC2\lib\site-packages\pytorch_lightning\trainer\trainer.py", line 898, in _validate_impl
    results = self._run(model, ckpt_path=self.ckpt_path)
  File "C:\Users\Jordan\anaconda3\envs\EC2\lib\site-packages\pytorch_lightning\trainer\trainer.py", line 1237, in _run
    results = self._run_stage()
  File "C:\Users\Jordan\anaconda3\envs\EC2\lib\site-packages\pytorch_lightning\trainer\trainer.py", line 1321, in _run_stage
    return self._run_evaluate()
  File "C:\Users\Jordan\anaconda3\envs\EC2\lib\site-packages\pytorch_lightning\trainer\trainer.py", line 1366, in _run_evaluate
    eval_loop_results = self._evaluation_loop.run()
  File "C:\Users\Jordan\anaconda3\envs\EC2\lib\site-packages\pytorch_lightning\loops\base.py", line 204, in run
    self.advance(*args, **kwargs)
  File "C:\Users\Jordan\anaconda3\envs\EC2\lib\site-packages\pytorch_lightning\loops\dataloader\evaluation_loop.py", line 153, in advance
    dl_outputs = self.epoch_loop.run(self._data_fetcher, dl_max_batches, kwargs)
  File "C:\Users\Jordan\anaconda3\envs\EC2\lib\site-packages\pytorch_lightning\loops\base.py", line 204, in run
    self.advance(*args, **kwargs)
  File "C:\Users\Jordan\anaconda3\envs\EC2\lib\site-packages\pytorch_lightning\loops\epoch\evaluation_epoch_loop.py", line 127, in advance
    output = self._evaluation_step(**kwargs)
  File "C:\Users\Jordan\anaconda3\envs\EC2\lib\site-packages\pytorch_lightning\loops\epoch\evaluation_epoch_loop.py", line 222, in _evaluation_step
    output = self.trainer._call_strategy_hook("validation_step", *kwargs.values())
  File "C:\Users\Jordan\anaconda3\envs\EC2\lib\site-packages\pytorch_lightning\trainer\trainer.py", line 1766, in _call_strategy_hook
    output = fn(*args, **kwargs)
  File "C:\Users\Jordan\anaconda3\envs\EC2\lib\site-packages\pytorch_lightning\strategies\strategy.py", line 344, in validation_step
    return self.model.validation_step(*args, **kwargs)
  File "C:\Users\Jordan\Learning\UVM\Research Projects\Novel-Feature-Detector\net.py", line 116, in validation_step
    logits = self.forward(x, get_activations=True)
  File "C:\Users\Jordan\Learning\UVM\Research Projects\Novel-Feature-Detector\net.py", line 40, in forward
    x = self.conv_layers[conv_count](x)
  File "C:\Users\Jordan\anaconda3\envs\EC2\lib\site-packages\torch\nn\modules\module.py", line 1110, in _call_impl
    return forward_call(*input, **kwargs)
  File "C:\Users\Jordan\anaconda3\envs\EC2\lib\site-packages\torch\nn\modules\conv.py", line 447, in forward
    return self._conv_forward(input, self.weight, self.bias)
  File "C:\Users\Jordan\anaconda3\envs\EC2\lib\site-packages\torch\nn\modules\conv.py", line 443, in _conv_forward
    return F.conv2d(input, weight, bias, self.stride,
RuntimeError: cuDNN error: CUDNN_STATUS_INTERNAL_ERROR
You can try to repro this exception using the following code snippet. If that doesn't trigger the error, please include your original repro script when reporting this issue.
import torch
torch.backends.cuda.matmul.allow_tf32 = True
torch.backends.cudnn.benchmark = True
torch.backends.cudnn.deterministic = False
torch.backends.cudnn.allow_tf32 = True
data = torch.randn([64, 3, 32, 32], dtype=torch.float, device='cuda', requires_grad=True)
net = torch.nn.Conv2d(3, 32, kernel_size=[3, 3], padding=[1, 1], stride=[1, 1], dilation=[1, 1], groups=1)
net = net.cuda().float()
out = net(data)
out.backward(torch.randn_like(out))
torch.cuda.synchronize()
ConvolutionParams
    data_type = CUDNN_DATA_FLOAT
    padding = [1, 1, 0]
    stride = [1, 1, 0]
    dilation = [1, 1, 0]
    groups = 1
    deterministic = false
    allow_tf32 = true
input: TensorDescriptor 0000024AAB8E9BF0
    type = CUDNN_DATA_FLOAT
    nbDims = 4
    dimA = 64, 3, 32, 32,
    strideA = 3072, 1024, 32, 1,
output: TensorDescriptor 0000024AAB8EA8A0
    type = CUDNN_DATA_FLOAT
    nbDims = 4
    dimA = 64, 32, 32, 32,
    strideA = 32768, 1024, 32, 1,
weight: FilterDescriptor 0000024AA82A3740
    type = CUDNN_DATA_FLOAT
    tensor_format = CUDNN_TENSOR_NCHW
    nbDims = 4
    dimA = 32, 3, 3, 3,
Pointer addresses:
    input: 000000130F6F4E00
    output: 0000001310D60000
    weight: 000000130F609000
During handling of the above exception, another exception occurred:
Traceback (most recent call last):
  File "C:\Users\Jordan\Learning\UVM\Research Projects\Novel-Feature-Detector\evolution.py", line 247, in <module>
    run()
  File "C:\Users\Jordan\Learning\UVM\Research Projects\Novel-Feature-Detector\evolution.py", line 200, in run
    solution_over_time, fitness_over_time = evolution(generations=n_iters, population_size=pop_size, num_children=num_children, tournament_size=tournament_size, num_winners=num_winners, evolution_type=run_name)
  File "C:\Users\Jordan\Learning\UVM\Research Projects\Novel-Feature-Detector\evolution.py", line 92, in evolution
    trainer.validate(net, dataloaders=data_module.val_dataloader(), verbose=False)
  File "C:\Users\Jordan\anaconda3\envs\EC2\lib\site-packages\pytorch_lightning\trainer\trainer.py", line 851, in validate
    return self._call_and_handle_interrupt(self._validate_impl, model, dataloaders, ckpt_path, verbose, datamodule)
  File "C:\Users\Jordan\anaconda3\envs\EC2\lib\site-packages\pytorch_lightning\trainer\trainer.py", line 739, in _call_and_handle_interrupt
    self._teardown()
  File "C:\Users\Jordan\anaconda3\envs\EC2\lib\site-packages\pytorch_lightning\trainer\trainer.py", line 1301, in _teardown
    self.strategy.teardown()
  File "C:\Users\Jordan\anaconda3\envs\EC2\lib\site-packages\pytorch_lightning\strategies\single_device.py", line 96, in teardown
    self.lightning_module.cpu()
  File "C:\Users\Jordan\anaconda3\envs\EC2\lib\site-packages\pytorch_lightning\core\mixins\device_dtype_mixin.py", line 147, in cpu
    return super().cpu()
  File "C:\Users\Jordan\anaconda3\envs\EC2\lib\site-packages\torch\nn\modules\module.py", line 718, in cpu
    return self._apply(lambda t: t.cpu())
  File "C:\Users\Jordan\anaconda3\envs\EC2\lib\site-packages\torch\nn\modules\module.py", line 578, in _apply
    module._apply(fn)
  File "C:\Users\Jordan\anaconda3\envs\EC2\lib\site-packages\torch\nn\modules\module.py", line 601, in _apply
    param_applied = fn(param)
  File "C:\Users\Jordan\anaconda3\envs\EC2\lib\site-packages\torch\nn\modules\module.py", line 718, in <lambda>
    return self._apply(lambda t: t.cpu())
RuntimeError: [enforce fail at C:\cb\pytorch_1000000000000\work\c10\core\impl\alloc_cpu.cpp:81] data. DefaultCPUAllocator: not enough memory: you tried to allocate 16777216 bytes.